<?xml version="1.0" ?>
<robot name="bumblebee_depth_camera">
  <joint name="depth_camera_joint" type="fixed">
    <parent link="base_link"/>
    <child link="depth_camera_link"/>
    <origin rpy="-1.57  0  -1.57" xyz="0.1    0     0.035"/>
    <axis xyz="0  0  1"/>
    <limit effort="0.0" lower="0.0" upper="0.0" velocity="0.0"/>
  </joint>
  <joint name="/imu_joint" type="fixed">
    <parent link="base_link"/>
    <child link="/imu_link"/>
    <origin rpy="0  0  0" xyz="0  0  0"/>
    <axis xyz="1  0  0"/>
    <limit effort="0.0" lower="0.0" upper="0.0" velocity="0.0"/>
  </joint>
  <joint name="rotor_0_joint" type="revolute">
    <parent link="base_link"/>
    <child link="rotor_0"/>
    <origin rpy="0  0  0" xyz="0.1868 -0.15    0.08"/>
    <axis xyz="0  0  1"/>
    <limit effort="0.0" lower="-1e+16" upper="1e+16" velocity="0.0"/>
  </joint>
  <joint name="rotor_4_joint" type="revolute">
    <parent link="base_link"/>
    <child link="rotor_4"/>
    <origin rpy="0  0  0" xyz="0.1868 -0.15   -0.02"/>
    <axis xyz="0  0  1"/>
    <limit effort="0.0" lower="-1e+16" upper="1e+16" velocity="0.0"/>
  </joint>
  <joint name="rotor_1_joint" type="revolute">
    <parent link="base_link"/>
    <child link="rotor_1"/>
    <origin rpy="0  0  0" xyz="-0.1758  0.151   0.08"/>
    <axis xyz="0  0  1"/>
    <limit effort="0.0" lower="-1e+16" upper="1e+16" velocity="0.0"/>
  </joint>
  <joint name="rotor_5_joint" type="revolute">
    <parent link="base_link"/>
    <child link="rotor_5"/>
    <origin rpy="0  0  0" xyz="-0.1758  0.151  -0.01"/>
    <axis xyz="0  0  1"/>
    <limit effort="0.0" lower="-1e+16" upper="1e+16" velocity="0.0"/>
  </joint>
  <joint name="rotor_2_joint" type="revolute">
    <parent link="base_link"/>
    <child link="rotor_2"/>
    <origin rpy="0  0  0" xyz="0.1848  0.15    0.08"/>
    <axis xyz="0  0  1"/>
    <limit effort="0.0" lower="-1e+16" upper="1e+16" velocity="0.0"/>
  </joint>
  <joint name="rotor_6_joint" type="revolute">
    <parent link="base_link"/>
    <child link="rotor_6"/>
    <origin rpy="0  0  0" xyz="0.1848  0.15   -0.01"/>
    <axis xyz="0  0  1"/>
    <limit effort="0.0" lower="-1e+16" upper="1e+16" velocity="0.0"/>
  </joint>
  <joint name="rotor_3_joint" type="revolute">
    <parent link="base_link"/>
    <child link="rotor_3"/>
    <origin rpy="0  0  0" xyz="-0.1778 -0.151   0.08"/>
    <axis xyz="0  0  1"/>
    <limit effort="0.0" lower="-1e+16" upper="1e+16" velocity="0.0"/>
  </joint>
  <joint name="rotor_7_joint" type="revolute">
    <parent link="base_link"/>
    <child link="rotor_7"/>
    <origin rpy="0  0  0" xyz="-0.1778 -0.151  -0.01"/>
    <axis xyz="0  0  1"/>
    <limit effort="0.0" lower="-1e+16" upper="1e+16" velocity="0.0"/>
  </joint>
  <link name="base_link">
    <inertial>
      <mass value="1.5"/>
      <origin rpy="0  0  0" xyz="0  0  0"/>
      <inertia ixx="0.029125" ixy="0" ixz="0" iyy="0.029125" iyz="0" izz="0.055225"/>
    </inertial>
    <collision name="base_link_inertia_collision">
      <origin rpy="0  0  0" xyz="0  0  0"/>
      <geometry>
        <box size="0.47 0.47 0.11"/>
      </geometry>
    </collision>
    <visual name="base_link_inertia_visual">
      <origin rpy="1.57079  0       0" xyz="0     0     0.015"/>
      <geometry>
        <mesh filename="package://px4/Tools/sitl_gazebo/models/rotors_description/meshes/bumblebee.stl" scale="0.001 0.001 0.001"/>
      </geometry>
    </visual>
  </link>
  <link name="/imu_link">
    <inertial>
      <mass value="0.015"/>
      <origin rpy="0  0  0" xyz="0  0  0"/>
      <inertia ixx="1e-05" ixy="0" ixz="0" iyy="1e-05" iyz="0" izz="1e-05"/>
    </inertial>
  </link>
  <link name="rotor_0">
    <inertial>
      <mass value="0.005"/>
      <origin rpy="0  0  0" xyz="0  0  0"/>
      <inertia ixx="9.75e-07" ixy="0" ixz="0" iyy="0.000273104" iyz="0" izz="0.000274004"/>
    </inertial>
    <collision name="rotor_0_collision">
      <origin rpy="0  0  0" xyz="0  0  0"/>
      <geometry>
        <cylinder length="0.005" radius="0.128"/>
      </geometry>
    </collision>
    <visual name="rotor_0_visual">
      <origin rpy="0  0  0" xyz="0  0  0"/>
      <geometry>
        <mesh filename="package://rotors_gazebo/models/rotors_description/meshes/iris_prop_ccw.dae" scale="1 1 1"/>
      </geometry>
    </visual>
  </link>
  <link name="rotor_4">
    <inertial>
      <mass value="0.005"/>
      <origin rpy="0  0  0" xyz="0  0  0"/>
      <inertia ixx="9.75e-07" ixy="0" ixz="0" iyy="0.000273104" iyz="0" izz="0.000274004"/>
    </inertial>
    <collision name="rotor_4_collision">
      <origin rpy="3.14  0    0" xyz="0  0  0"/>
      <geometry>
        <cylinder length="0.005" radius="0.128"/>
      </geometry>
    </collision>
    <visual name="rotor_4_visual">
      <origin rpy="0  0  0" xyz="0  0  0"/>
      <geometry>
        <mesh filename="package://rotors_gazebo/models/rotors_description/meshes/iris_prop_cw.dae" scale="1 1 1"/>
      </geometry>
    </visual>
  </link>
  <link name="rotor_1">
    <inertial>
      <mass value="0.005"/>
      <origin rpy="0  0  0" xyz="0  0  0"/>
      <inertia ixx="9.75e-07" ixy="0" ixz="0" iyy="0.000273104" iyz="0" izz="0.000274004"/>
    </inertial>
    <collision name="rotor_1_collision">
      <origin rpy="0  0  0" xyz="0  0  0"/>
      <geometry>
        <cylinder length="0.005" radius="0.128"/>
      </geometry>
    </collision>
    <visual name="rotor_1_visual">
      <origin rpy="0  0  0" xyz="0  0  0"/>
      <geometry>
        <mesh filename="package://rotors_gazebo/models/rotors_description/meshes/iris_prop_ccw.dae" scale="1 1 1"/>
      </geometry>
    </visual>
  </link>
  <link name="rotor_5">
    <inertial>
      <mass value="0.005"/>
      <origin rpy="0  0  0" xyz="0  0  0"/>
      <inertia ixx="9.75e-07" ixy="0" ixz="0" iyy="0.000273104" iyz="0" izz="0.000274004"/>
    </inertial>
    <collision name="rotor_5_collision">
      <origin rpy="0  0  0" xyz="0  0  0"/>
      <geometry>
        <cylinder length="0.005" radius="0.128"/>
      </geometry>
    </collision>
    <visual name="rotor_5_visual">
      <origin rpy="3.14  0    0" xyz="0  0  0"/>
      <geometry>
        <mesh filename="package://rotors_gazebo/models/rotors_description/meshes/iris_prop_cw.dae" scale="1 1 1"/>
      </geometry>
    </visual>
  </link>
  <link name="rotor_2">
    <inertial>
      <mass value="0.005"/>
      <origin rpy="0  0  0" xyz="0  0  0"/>
      <inertia ixx="9.75e-07" ixy="0" ixz="0" iyy="0.000273104" iyz="0" izz="0.000274004"/>
    </inertial>
    <collision name="rotor_2_collision">
      <origin rpy="0  0  0" xyz="0  0  0"/>
      <geometry>
        <cylinder length="0.005" radius="0.128"/>
      </geometry>
    </collision>
    <visual name="rotor_2_visual">
      <origin rpy="0  0  0" xyz="0  0  0"/>
      <geometry>
        <mesh filename="package://rotors_gazebo/models/rotors_description/meshes/iris_prop_cw.dae" scale="1 1 1"/>
      </geometry>
    </visual>
  </link>
  <link name="rotor_6">
    <inertial>
      <mass value="0.005"/>
      <origin rpy="0  0  0" xyz="0  0  0"/>
      <inertia ixx="9.75e-07" ixy="0" ixz="0" iyy="0.000273104" iyz="0" izz="0.000274004"/>
    </inertial>
    <collision name="rotor_6_collision">
      <origin rpy="0  0  0" xyz="0  0  0"/>
      <geometry>
        <cylinder length="0.005" radius="0.128"/>
      </geometry>
    </collision>
    <visual name="rotor_6_visual">
      <origin rpy="3.14  0    0" xyz="0  0  0"/>
      <geometry>
        <mesh filename="package://rotors_gazebo/models/rotors_description/meshes/iris_prop_ccw.dae" scale="1 1 1"/>
      </geometry>
    </visual>
  </link>
  <link name="rotor_3">
    <inertial>
      <mass value="0.005"/>
      <origin rpy="0  0  0" xyz="0  0  0"/>
      <inertia ixx="9.75e-07" ixy="0" ixz="0" iyy="0.000273104" iyz="0" izz="0.000274004"/>
    </inertial>
    <collision name="rotor_3_collision">
      <origin rpy="0  0  0" xyz="0  0  0"/>
      <geometry>
        <cylinder length="0.005" radius="0.128"/>
      </geometry>
    </collision>
    <visual name="rotor_3_visual">
      <origin rpy="0  0  0" xyz="0  0  0"/>
      <geometry>
        <mesh filename="package://rotors_gazebo/models/rotors_description/meshes/iris_prop_cw.dae" scale="1 1 1"/>
      </geometry>
    </visual>
  </link>
  <link name="rotor_7">
    <inertial>
      <mass value="0.005"/>
      <origin rpy="0  0  0" xyz="0  0  0"/>
      <inertia ixx="9.75e-07" ixy="0" ixz="0" iyy="0.000273104" iyz="0" izz="0.000274004"/>
    </inertial>
    <collision name="rotor_7_collision">
      <origin rpy="0  0  0" xyz="0  0  0"/>
      <geometry>
        <cylinder length="0.005" radius="0.128"/>
      </geometry>
    </collision>
    <visual name="rotor_7_visual">
      <origin rpy="3.14  0    0" xyz="0  0  0"/>
      <geometry>
        <mesh filename="package://rotors_gazebo/models/rotors_description/meshes/iris_prop_ccw.dae" scale="1 1 1"/>
      </geometry>
    </visual>
  </link>
  <link name="depth_camera_link">
    <inertial>
      <mass value="0.01"/>
      <origin rpy="0  0  0" xyz="0.01   0.025  0.025"/>
      <inertia ixx="4.15e-6" ixy="0" ixz="0" iyy="2.407e-6" iyz="0" izz="2.407e-6"/>
    </inertial>
    <visual name="depth_camera_visual">
      <origin rpy="0  0  0" xyz="0  0  0"/>
      <geometry>
        <mesh filename="package://px4/Tools/sitl_gazebo/models/realsense_camera/meshes/realsense.dae" scale="1.0 1.0 1.0"/>
      </geometry>
    </visual>
  </link>
</robot>
