<?xml version="1.0" ?>
<robot name="car" xmlns:xacro="http://ros.org/wiki/xacro">


    <link name="base">

        <inertial>
            <mass value="2.0"/>
            <inertia ixx="1.66666665" iyy="1.666666665" izz="3.3333335" ixy="0" ixz="0" iyz="0"/>
        </inertial>

        <collision>

            <geometry>
                <box size="1 1 3"/>
            </geometry>

        </collision>

        <visual>
            <geometry>
                <box size="1 1 3"/>
            </geometry>

            <material name="silver">
                <color rgba="0.75 0.75 0.75 1"/>
            </material>
        </visual>

    </link>

    <link name="front_right_wheel">
    
        <inertial> 
            <mass value="0.1"/>
            <inertia ixx="6.3333e-5" iyy="6.3333e-5" izz="0.000125" ixy="0" ixz="0" iyz="0"/>
        </inertial>
        <collision>
            <geometry>
                <cylinder length="0.01" radius="0.05"/>
            </geometry>
        </collision>

        <visual>
            <geometry>
                <cylinder length="0.01" radius="0.05"/>
            </geometry>
            <material name="black">
                <color rgba="0 0 0 1"/>
            </material>
        </visual>
    </link>


    <joint name="front_right_wheel_joint" type="continuous">
        <axis xyz="0 0 1"/>
        <parent link="base"/>
        <child link="front_right_wheel"/>
        <origin rpy="0 -1.5708 0" xyz="0.5 -0.5 -1.5"/>
    </joint>


    <link name="front_left_wheel">
         <inertial> 
            <mass value="0.1"/>
            <inertia ixx="6.2708e-5" iyy="6.2708e-5" izz="0.000125" ixy="0" ixz="0" iyz="0"/>
        </inertial>
        <collision>
            <geometry>
                <cylinder length="0.01" radius="0.05"/>
            </geometry>
        </collision>

        <visual>
            <geometry>
                <cylinder length="0.01" radius="0.05"/>
            </geometry>
            <material name="black"/>
        </visual>
    </link>

    <joint name="front_left_wheel_joint" type="continuous">
        <axis xyz="0 0 1"/>
        <parent link="base"/>
        <child link="front_left_wheel"/>
        <origin rpy="0 -1.5708 0" xyz="0.5 0.5 -1.5"/>
    </joint> 


    <link name="back_right_wheel">
         <inertial> 
            <mass value="0.1"/>
            <inertia ixx="6.2708e-5" iyy="6.2708e-5" izz="0.000125" ixy="0" ixz="0" iyz="0"/>
        </inertial>
        <collision>
            <geometry>
                <cylinder length="0.01" radius="0.05"/>
            </geometry>
        </collision>

        <visual>
            <geometry>
                <cylinder length="0.01" radius="0.05"/>
            </geometry>
            <material name="black">
                <color rgba="0 0 0 1"/>
            </material>
        </visual>
    </link>


    <joint name="back_right_wheel_joint" type="continuous">
        <axis xyz="0 0 1"/>
        <parent link="base"/>
        <child link="back_right_wheel"/>
        <origin rpy="0 -1.5708 0" xyz="-0.5 -0.5 -1.5"/>
    </joint>


    <link name="back_left_wheel">
        <inertial> 
            <mass value="0.1"/>
            <inertia ixx="6.2708e-5" iyy="6.2708e-5" izz="0.000125" ixy="0" ixz="0" iyz="0"/>
        </inertial>
        <collision>
            <geometry>
                <cylinder length="0.01" radius="0.05"/>
            </geometry>
        </collision>

        <visual>
            <geometry>
                <cylinder length="0.01" radius="0.05"/>
            </geometry>
            <material name="black"/>
        </visual>
    </link>

    <joint name="back_left_wheel_joint" type="continuous">
        <axis xyz="0 0 1"/>
        <parent link="base"/>
        <child link="back_left_wheel"/>
        <origin rpy="0 -1.5708 0" xyz="-0.5 0.5 -1.5"/>
    </joint> 

    <!-- gazebo -->
    <gazebo reference="base">
        <material>Gazebo/Grey</material>
        <mu1>0.1</mu1>
        <mu2>0.1</mu2>
    </gazebo>
    <gazebo reference="back_left_wheel">
        <material>Gazebo/Black</material>
        <mu1>0.1</mu1>
        <mu2>0.1</mu2>
    </gazebo>
    <gazebo reference="back_right_wheel">
        <material>Gazebo/Black</material>
        <mu1>0.1</mu1>
        <mu2>0.1</mu2>
    </gazebo>
    <gazebo reference="front_left_wheel">
        <material>Gazebo/Black</material>
        <mu1>0.1</mu1>
        <mu2>0.1</mu2>
    </gazebo>
    <gazebo reference="front_right_wheel">
        <material>Gazebo/Black</material>
        <mu1>0.1</mu1>
        <mu2>0.1</mu2>
    </gazebo>

    <transmission name="back_left">
        <type>transmission_interface/SimpleTransmission</type>
        <joint name="back_left_wheel_joint">
            <hardwareInterface>hardware_interface/VelocityJointInterface</hardwareInterface>
            <!--<hardwareInterface>VelocityJointInterface</hardwareInterface>-->
            </joint>
        <actuator name="back_left_motor">
            <mechanicalReduction>100</mechanicalReduction>
        </actuator>
    </transmission>
    <transmission name="back_right">
        <type>transmission_interface/SimpleTransmission</type>
        <joint name="back_right_wheel_joint">
            <hardwareInterface>hardware_interface/VelocityJointInterface</hardwareInterface>
            <!--<hardwareInterface>VelocityJointInterface</hardwareInterface>-->
            </joint>
        <actuator name="back_right_motor">
            <mechanicalReduction>100</mechanicalReduction>
        </actuator>
    </transmission>
    <transmission name="front_left">
        <type>transmission_interface/SimpleTransmission</type>
        <joint name="front_left_wheel_joint">
            <hardwareInterface>hardware_interface/VelocityJointInterface</hardwareInterface>
            <!--<hardwareInterface>VelocityJointInterface</hardwareInterface>-->
            </joint>
        <actuator name="front_left_motor">
            <mechanicalReduction>100</mechanicalReduction>
        </actuator>
    </transmission>
    <transmission name="front_right">
        <type>transmission_interface/SimpleTransmission</type>
        <joint name="front_right_wheel_joint">
            <hardwareInterface>hardware_interface/VelocityJointInterface</hardwareInterface>
            <!--<hardwareInterface>VelocityJointInterface</hardwareInterface>-->
            </joint>
        <actuator name="front_right_motor">
            <mechanicalReduction>100</mechanicalReduction>
        </actuator>
    </transmission>

    <gazebo>
        <plugin name="gazebo_ros_control" filename="libgazebo_ros_control.so">
        <robotNamespace>/</robotNamespace>
        </plugin>
    </gazebo>
    
</robot>
